<?xml version="1.0"?>


<root xmlns:xi="http://www.w3.org/2001/XInclude"
	xmlns:gazebo="http://playerstage.sourceforge.net/gazebo/xmlschema/#gz"
	xmlns:model="http://playerstage.sourceforge.net/gazebo/xmlschema/#model"
	xmlns:sensor="http://playerstage.sourceforge.net/gazebo/xmlschema/#sensor"
	xmlns:body="http://playerstage.sourceforge.net/gazebo/xmlschema/#body"
	xmlns:geom="http://playerstage.sourceforge.net/gazebo/xmlschema/#geom"
	xmlns:joint="http://playerstage.sourceforge.net/gazebo/xmlschema/#joint"
	xmlns:controller="http://playerstage.sourceforge.net/gazebo/xmlschema/#controller"
	xmlns:interface="http://playerstage.sourceforge.net/gazebo/xmlschema/#interface"
	xmlns:rendering="http://playerstage.sourceforge.net/gazebo/xmlschema/#rendering"
	xmlns:renderable="http://playerstage.sourceforge.net/gazebo/xmlschema/#renderable"
	xmlns:physics="http://playerstage.sourceforge.net/gazebo/xmlschema/#physics"
	xmlns:xacro="http://ros.org/wiki/xacro">

<xacro:include filename="$(find kinova_description)/urdf/kinova_inertial.xacro" />


    <xacro:property name="J_PI" value="3.1415926535897931" />

    <xacro:macro name="kinova_armlink" params="link_name link_mesh ring_mesh:=ring_big use_ring_mesh:=false mesh_no">
        <link name="${link_name}">
            <visual>
                <geometry>
                    <mesh
                        filename="package://kinova_description/meshes/${link_mesh}.dae"/>
                </geometry>
                <material name="carbon_fiber">
                    <color rgba="0.792156862745098 0.819607843137255 0.933333333333333 1" />
                </material>
            </visual>

           <!-- Adding ring to the model -->
           <xacro:if value="${use_ring_mesh}">
             <visual>
                <geometry>
                    <mesh
                        filename="package://kinova_description/meshes/${ring_mesh}.STL"/>
                </geometry>
             </visual>
           </xacro:if>

            <collision>
                <geometry>
                    <mesh
                        filename="package://kinova_description/meshes/${link_mesh}.dae"/>
                </geometry>
            </collision>
            <xacro:kinova_inertial mesh_no="${mesh_no}"/>

            <gazebo reference="[links in contact]">
              <kp>1000000.0</kp>
              <kd>1.0</kd>
              <mu1>1.0</mu1>
              <mu2>1.0</mu2>
              <minDepth>0.001</minDepth>
            </gazebo>
        </link>

      <gazebo reference="${link_name}">
          <material>Gazebo/DarkGrey</material>
      </gazebo>

    </xacro:macro>

  <xacro:macro name="kinova_armjoint" params="joint_name type parent child joint_axis_xyz joint_origin_xyz joint_origin_rpy joint_lower_limit joint_upper_limit fixed:=false">
    <joint name="${joint_name}" type="${type}">
        <parent link="${parent}"/>
        <child link="${child}"/>
        <axis xyz="${joint_axis_xyz}"/>
        <limit effort="60" velocity="6.28" lower="${joint_lower_limit}" upper="${joint_upper_limit}"/>
        <origin xyz="${joint_origin_xyz}" rpy="${joint_origin_rpy}"/>
        <dynamics damping="1.7" friction="0.0"/>
     </joint>
   <xacro:unless value="${fixed}">
     <gazebo reference="${joint_name}">
        <implicitSpringDamper>1</implicitSpringDamper>
     </gazebo>

     <transmission name="${joint_name}_trans">
        <type>transmission_interface/SimpleTransmission</type>
        <joint name="${joint_name}">
          <hardwareInterface>EffortJointInterface</hardwareInterface>
        </joint>
        <actuator name="${joint_name}_actuator">
          <hardwareInterface>EffortJointInterface</hardwareInterface>
        <mechanicalReduction>160</mechanicalReduction>
        </actuator>
     </transmission>
   </xacro:unless>
  </xacro:macro>


    <xacro:macro name="kinova_virtual_link" params="link_name">
        <link name="${link_name}">
            <!--visual>
                <geometry>
                    <box size = "0.01 0.01 0.01"/>
                </geometry>
            </visual>
            <collision>
                <geometry>
                    <box size = "0.01 0.01 0.01"/>
                </geometry>
            </collision-->
        </link>
    </xacro:macro>

    <xacro:macro name="kinova_virtual_joint" params="joint_name type parent child joint_axis_xyz joint_origin_xyz joint_origin_rpy joint_lower_limit joint_upper_limit">
    <joint name="${joint_name}" type="${type}">
        <parent link="${parent}"/>
        <child link="${child}"/>
        <axis xyz="${joint_axis_xyz}"/>
        <limit effort="60" velocity="3.35" lower="${joint_lower_limit}" upper="${joint_upper_limit}"/>
        <origin xyz="${joint_origin_xyz}" rpy="${joint_origin_rpy}"/>
     </joint>
    </xacro:macro>


    <xacro:macro name="kinova_finger" params="prefix finger_number hand finger_origin_xyz finger_origin_rpy">

        <link name="${prefix}link_finger_${finger_number}">
              <visual>
                  <geometry>
                      <mesh
                          filename="package://kinova_description/meshes/finger_proximal.dae"/>
                  </geometry>
              </visual>

              <collision>
                  <geometry>
                      <mesh
                          filename="package://kinova_description/meshes/finger_proximal.dae"/>
                  </geometry>
              </collision>
              <xacro:kinova_inertial mesh_no="1"/>
        </link>

        <gazebo reference="${prefix}link_finger_${finger_number}">
            <material>Gazebo/Grey</material>
        </gazebo>

        <joint name="${prefix}joint_finger_${finger_number}" type="revolute">
            <parent link="${hand}"/>
            <child link="${prefix}link_finger_${finger_number}"/>
            <axis xyz="0 0 1"/>
            <origin xyz="${finger_origin_xyz}" rpy="${finger_origin_rpy}"/>
            <limit lower="0" upper="2" effort="30" velocity="5"/>
            <dynamics damping="0.7" friction="0.0"/>
        </joint>
        <transmission name="${prefix}joint_finger_${finger_number}_trans">
          <type>transmission_interface/SimpleTransmission</type>
          <joint name="${prefix}joint_finger_${finger_number}">
            <hardwareInterface>EffortJointInterface</hardwareInterface>
          </joint>
          <actuator name="${prefix}joint_finger_${finger_number}_actuator">
          <hardwareInterface>EffortJointInterface</hardwareInterface>
          <mechanicalReduction>1</mechanicalReduction>
          </actuator>
        </transmission>

        <link name="${prefix}link_finger_tip_${finger_number}">
            <visual>
                <geometry>
                    <mesh
                        filename="package://kinova_description/meshes/finger_distal.dae"/>
                </geometry>
            </visual>

            <collision>
                <geometry>
                    <mesh
                        filename="package://kinova_description/meshes/finger_distal.dae"/>
                </geometry>
            </collision>
            <xacro:kinova_inertial mesh_no="58"/>
      </link>

      <gazebo reference="${prefix}link_finger_tip_${finger_number}">
          <material>Gazebo/Grey</material>
      </gazebo>

      <joint name="${prefix}joint_finger_tip_${finger_number}" type="revolute">
          <parent link="${prefix}link_finger_${finger_number}"/>
          <child link="${prefix}link_finger_tip_${finger_number}"/>
          <axis xyz="0 0 1"/>
          <origin xyz="0.044 -0.003 0" rpy="0 0 0.3"/>
          <limit lower="0" upper="2" effort="30" velocity="5"/>
          <dynamics damping="0.0" friction="0.0"/>
          <mimic joint="${prefix}joint_finger_${finger_number}" multiplier="0.6" offset="0.0"/>
      </joint>

    </xacro:macro>


</root>
